<?xml version="1.0" ?>
<!-- This URDF was automatically created by SolidWorks to URDF Exporter! Originally created by Stephen Brawner (brawner@gmail.com) 
     Commit Version: 1.6.0-4-g7f85cfe  Build Version: 1.6.7995.38578
     For more information, please see http://wiki.ros.org/sw_urdf_exporter -->



<robot
  name="barista_robot" xmlns:xacro="http://ros.org/wiki/xacro">


  <xacro:macro name="grey_color">
      <visual>
      <material>
          <ambient>0.250980392156863 0.250980392156863 0.250980392156863 1</ambient>
          <diffuse>0.250980392156863 0.250980392156863 0.250980392156863 1</diffuse>
          <specular>0.1 0.1 0.1 1</specular>
          <emissive>0 0 0 0</emissive>
      </material>
      </visual>
  </xacro:macro>
  
  <xacro:macro name="red_color">
      <visual>
      <material>
          <ambient>1 0.501960784313725 0.501960784313725 1</ambient>
          <diffuse> 0.501960784313725 0.501960784313725 1 </diffuse>
          <specular>0.1 0.1 0.1 1</specular>
          <emissive>0 0 0 0</emissive>
      </material>
      </visual>
  </xacro:macro>


  <link name="world" />  



  <joint name="fixed_base" type="fixed">
      <parent link="world" />

      <child link="base_link" /> 

  </joint>


  <link
    name="base_link">
    <inertial>
      <origin
        xyz="0.00383011072526205 0.000928737788211999 0.457157273514301"
        rpy="0 0 0" />
      <mass
        value="26.0610113726114" />
      <inertia
        ixx="1.87464355002268"
        ixy="-2.53087124754727E-05"
        ixz="-0.014715478905658"
        iyy="1.87476517415076"
        iyz="-0.00356830501660734"
        izz="0.11834660940371" />
    </inertial>
    <visual>
      <origin
        xyz="0 0 0"
        rpy="0 0 0" />
      <geometry>
        <mesh
          filename="package://barista_robot/meshes/base_link.STL" />
      </geometry>
      <material
        name="">
        <color
          rgba="0.250980392156863 0.250980392156863 0.250980392156863 1" />
      </material>
    </visual>
    <collision>
      <origin
        xyz="0 0 0"
        rpy="0 0 0" />
      <geometry>
        <mesh
          filename="package://barista_robot/meshes/base_link.STL" />
      </geometry>
    </collision>
  </link>
  <link
    name="robot_base">
    <inertial>
      <origin
        xyz="-8.25728228697777E-05 0.0620784408679793 -0.00108614239219215"
        rpy="0 0 0" />
      <mass
        value="0.01" />
      <inertia
        ixx="0.0031562038651467"
        ixy="-2.76687841703515E-06"
        ixz="-8.66772096465886E-07"
        iyy="0.00496373152249205"
        iyz="-5.19354690470229E-05"
        izz="0.00358674288427154" />
    </inertial>
    <visual>
      <origin
        xyz="0 0 0"
        rpy="0 0 0" />
      <geometry>
        <mesh
          filename="package://barista_robot/meshes/robot_base.STL" />
      </geometry>
      <material
        name="">
        <color
          rgba="1 0.501960784313725 0.501960784313725 1" />
      </material>
    </visual>
    <collision>
      <origin
        xyz="0 0 0"
        rpy="0 0 0" />
      <geometry>
        <mesh
          filename="package://barista_robot/meshes/robot_base.STL" />
      </geometry>
    </collision>
  </link>
  <joint
    name="robot_base_joint"
    type="fixed">
    <origin
      xyz="0.0076472 0.0018543 0.91276"
      rpy="1.5688 0.0083757 -0.0011068" />
    <parent
      link="base_link" />
    <child
      link="robot_base" />
    <axis
      xyz="0 0 0" />
  </joint>
  <link
    name="link_1">
    <inertial>
      <origin
        xyz="5.29382164128232E-08 0.0850432466695747 0.0128932752104662"
        rpy="0 0 0" />
      <mass
        value="0.01" />
      <inertia
        ixx="0.0144417466716968"
        ixy="-1.76720854918668E-07"
        ixz="1.27033528349741E-07"
        iyy="0.0120175511780906"
        iyz="-0.000178584855651563"
        izz="0.0128349355041157" />
    </inertial>
    <visual>
      <origin
        xyz="0 0 0"
        rpy="0 0 0" />
      <geometry>
        <mesh
          filename="package://barista_robot/meshes/link_1.STL" />
      </geometry>
      <material
        name="">
        <color
          rgba="1 0.501960784313725 0.501960784313725 1" />
      </material>
    </visual>
    <collision>
      <origin
        xyz="0 0 0"
        rpy="0 0 0" />
      <geometry>
        <mesh
          filename="package://barista_robot/meshes/link_1.STL" />
      </geometry>
    </collision>
  </link>
  <joint
    name="link_1_joint"
    type="revolute">
    <origin
      xyz="0 0.099247 0"
      rpy="0 0.46585 0" />
    <parent
      link="robot_base" />
    <child
      link="link_1" />
    <axis
      xyz="0 1 0" />
    <limit
      lower="-6.28"
      upper="6.28"
      effort="100.0"
      velocity="3.14" />
  </joint>
  <link
    name="link_2">
    <inertial>
      <origin
        xyz="-1.63530545009734E-06 0.211231437364917 0.152882713335174"
        rpy="0 0 0" />
      <mass
        value="0.01" />
      <inertia
        ixx="0.421785968792057"
        ixy="-4.66698955952136E-06"
        ixz="-8.61933981188834E-07"
        iyy="0.0183913103922809"
        iyz="0.000922257685442064"
        izz="0.418871238998585" />
    </inertial>
    <visual>
      <origin
        xyz="0 0 0"
        rpy="0 0 0" />
      <geometry>
        <mesh
          filename="package://barista_robot/meshes/link_2.STL" />
      </geometry>
      <material
        name="">
        <color
          rgba="1 0.501960784313725 0.501960784313725 1" />
      </material>
    </visual>
    <collision>
      <origin
        xyz="0 0 0"
        rpy="0 0 0" />
      <geometry>
        <mesh
          filename="package://barista_robot/meshes/link_2.STL" />
      </geometry>
    </collision>
  </link>
  <joint
    name="link_2_joint"
    type="revolute">
    <origin
      xyz="0 0.083054 0.024109"
      rpy="0 0 0" />
    <parent
      link="link_1" />
    <child
      link="link_2" />
    <axis
      xyz="0 0 1" />
    <limit
      lower="-6.28"
      upper="6.28"
      effort="100.0"
      velocity="3.14" />
  </joint>
  <link
    name="link_3">
    <inertial>
      <origin
        xyz="1.53110060815975E-06 0.265809569671053 0.0201295876152247"
        rpy="0 0 0" />
      <mass
        value="0.01" />
      <inertia
        ixx="0.198422158428495"
        ixy="4.85995234595538E-06"
        ixz="-1.51823787104821E-07"
        iyy="0.00626605018851334"
        iyz="0.00588106797289478"
        izz="0.197534307061617" />
    </inertial>
    <visual>
      <origin
        xyz="0 0 0"
        rpy="0 0 0" />
      <geometry>
        <mesh
          filename="package://barista_robot/meshes/link_3.STL" />
      </geometry>
      <material
        name="">
        <color
          rgba="1 0.501960784313725 0.501960784313725 1" />
      </material>
    </visual>
    <collision>
      <origin
        xyz="0 0 0"
        rpy="0 0 0" />
      <geometry>
        <mesh
          filename="package://barista_robot/meshes/link_3.STL" />
      </geometry>
    </collision>
  </link>
  <joint
    name="link_3_joint"
    type="revolute">
    <origin
      xyz="0 0.6126 0"
      rpy="0 0 0" />
    <parent
      link="link_2" />
    <child
      link="link_3" />
    <axis
      xyz="0 0 1" />
    <limit
      lower="-6.28"
      upper="6.28"
      effort="100.0"
      velocity="3.14" />
  </joint>
  <link
    name="link_4">
    <inertial>
      <origin
        xyz="-1.65409067374393E-06 0.00153987297982727 0.134078386407816"
        rpy="0 0 0" />
      <mass
        value="0.01" />
      <inertia
        ixx="0.00181788273252644"
        ixy="1.83030713911664E-08"
        ixz="-2.83699805857262E-08"
        iyy="0.00150425784838232"
        iyz="-4.60370793799838E-05"
        izz="0.00132306977239992" />
    </inertial>
    <visual>
      <origin
        xyz="0 0 0"
        rpy="0 0 0" />
      <geometry>
        <mesh
          filename="package://barista_robot/meshes/link_4.STL" />
      </geometry>
      <material
        name="">
        <color
          rgba="1 0.501960784313725 0.501960784313725 1" />
      </material>
    </visual>
    <collision>
      <origin
        xyz="0 0 0"
        rpy="0 0 0" />
      <geometry>
        <mesh
          filename="package://barista_robot/meshes/link_4.STL" />
      </geometry>
    </collision>
  </link>
  <joint
    name="link_4_joint"
    type="revolute">
    <origin
      xyz="0 0.57155 0"
      rpy="0 0 0" />
    <parent
      link="link_3" />
    <child
      link="link_4" />
    <axis
      xyz="0 0 1" />
    <limit
      lower="-6.28"
      upper="6.28"
      effort="100.0"
      velocity="3.14" />
  </joint>
  <link
    name="link_5">
    <inertial>
      <origin
        xyz="1.19754439253938E-07 0.107894811323263 0.00172520348120131"
        rpy="0 0 0" />
      <mass
        value="0.01" />
      <inertia
        ixx="0.00143476123567499"
        ixy="-5.38094070829317E-09"
        ixz="4.87203904200569E-10"
        iyy="0.00122172827947616"
        iyz="-3.67653414285888E-05"
        izz="0.00112162874820744" />
    </inertial>
    <visual>
      <origin
        xyz="0 0 0"
        rpy="0 0 0" />
      <geometry>
        <mesh
          filename="package://barista_robot/meshes/link_5.STL" />
      </geometry>
      <material
        name="">
        <color
          rgba="1 0.501960784313725 0.501960784313725 1" />
      </material>
    </visual>
    <collision>
      <origin
        xyz="0 0 0"
        rpy="0 0 0" />
      <geometry>
        <mesh
          filename="package://barista_robot/meshes/link_5.STL" />
      </geometry>
    </collision>
  </link>
  <joint
    name="link_5_joint"
    type="revolute">
    <origin
      xyz="0 0.0023315 0.15004"
      rpy="0 0 0" />
    <parent
      link="link_4" />
    <child
      link="link_5" />
    <axis
      xyz="0 1 0" />
    <limit
      lower="-6.28"
      upper="6.28"
      effort="100.0"
      velocity="3.14" />
  </joint>
  <link
    name="link_6">
    <inertial>
      <origin
        xyz="2.81491482900798E-10 -0.000111459403922876 0.0639973256145779"
        rpy="0 0 0" />
      <mass
        value="0.01" />
      <inertia
        ixx="0.000263769355605864"
        ixy="-1.01386732524475E-11"
        ixz="2.90992081234016E-12"
        iyy="0.000265234926115791"
        iyz="8.54378486946284E-09"
        izz="0.000346928634455195" />
    </inertial>
    <visual>
      <origin
        xyz="0 0 0"
        rpy="0 0 0" />
      <geometry>
        <mesh
          filename="package://barista_robot/meshes/link_6.STL" />
      </geometry>
      <material
        name="">
        <color
          rgba="1 0.501960784313725 0.501960784313725 1" />
      </material>
    </visual>
    <collision>
      <origin
        xyz="0 0 0"
        rpy="0 0 0" />
      <geometry>
        <mesh
          filename="package://barista_robot/meshes/link_6.STL" />
      </geometry>
    </collision>
  </link>
  <joint
    name="link_6_joint"
    type="revolute">
    <origin
      xyz="0 0.11752 0.020667"
      rpy="0 0 0" />
    <parent
      link="link_5" />
    <child
      link="link_6" />
    <axis
      xyz="0 0 1" />
    <limit
      lower="-6.28"
      upper="6.28"
      effort="100.0"
      velocity="3.14" />
  </joint>
  <link
    name="gripper_base_link">
    <inertial>
      <origin
        xyz="0.000286947815021282 0.0323397938072079 0.000129565492640982"
        rpy="0 0 0" />
      <mass
        value="0.01" />
      <inertia
        ixx="0.000175809669038929"
        ixy="3.37704999012043E-10"
        ixz="-8.4322406184789E-09"
        iyy="0.000134409051306673"
        iyz="-1.12870831583151E-07"
        izz="0.000200275872123387" />
    </inertial>
    <visual>
      <origin
        xyz="0 0 0"
        rpy="0 0 0" />
      <geometry>
        <mesh
          filename="package://barista_robot/meshes/gripper_base_link.STL" />
      </geometry>
      <material
        name="">
        <color
          rgba="0.250980392156863 0.250980392156863 0.250980392156863 1" />
      </material>
    </visual>
    <collision>
      <origin
        xyz="0 0 0"
        rpy="0 0 0" />
      <geometry>
        <mesh
          filename="package://barista_robot/meshes/gripper_base_link.STL" />
      </geometry>
    </collision>
  </link>
  <joint
    name="gripper_base_link_joint"
    type="fixed">
    <origin
      xyz="0.00028751 -0.00010687 0.089124"
      rpy="1.5708 0 -3.1416" />
    <parent
      link="link_6" />
    <child
      link="gripper_base_link" />
    <axis
      xyz="0 0 0" />
  </joint>
  <link
    name="left_finger_1">
    <inertial>
      <origin
        xyz="0.0362255356799374 7.19353188127769E-11 -4.18730362437003E-05"
        rpy="0 0 0" />
      <mass
        value="0.001" />
      <inertia
        ixx="6.64066668853769E-06"
        ixy="-5.31597013723193E-14"
        ixz="-1.58101995539253E-14"
        iyy="1.70445818730747E-05"
        iyz="1.13977089624038E-11"
        izz="1.11317984671145E-05" />
    </inertial>
    <visual>
      <origin
        xyz="0 0 0"
        rpy="0 0 0" />
      <geometry>
        <mesh
          filename="package://barista_robot/meshes/left_finger_1.STL" />
      </geometry>
      <material
        name="">
        <color
          rgba="1 0.501960784313725 0.501960784313725 1" />
      </material>
    </visual>
    <collision>
      <origin
        xyz="0 0 0"
        rpy="0 0 0" />
      <geometry>
        <mesh
          filename="package://barista_robot/meshes/left_finger_1.STL" />
      </geometry>
    </collision>
  </link>
  <joint
    name="left_finger_1_joint"
    type="revolute">
    <origin
      xyz="-0.012412 0.061437 0"
      rpy="-3.1416 0 1.5708" />
    <parent
      link="gripper_base_link" />
    <child
      link="left_finger_1" />
    <axis
      xyz="0 0 1" />
    <limit
      lower="-3.14"
      upper="3.14"
      effort="100.0"
      velocity="3.14" />
  </joint>
  <link
    name="left_finger_2">
    <inertial>
      <origin
        xyz="0.0205613134938167 0.000122395880532089 -2.07266898089031E-10"
        rpy="0 0 0" />
      <mass
        value="0.001" />
      <inertia
        ixx="2.6334781516959E-07"
        ixy="1.21659199704823E-13"
        ixz="-2.86602553488723E-14"
        iyy="1.51982892750927E-06"
        iyz="1.85154990863069E-13"
        izz="1.6846267695367E-06" />
    </inertial>
    <visual>
      <origin
        xyz="0 0 0"
        rpy="0 0 0" />
      <geometry>
        <mesh
          filename="package://barista_robot/meshes/left_finger_2.STL" />
      </geometry>
      <material
        name="">
        <color
          rgba="1 0.501960784313725 0.501960784313725 1" />
      </material>
    </visual>
    <collision>
      <origin
        xyz="0 0 0"
        rpy="0 0 0" />
      <geometry>
        <mesh
          filename="package://barista_robot/meshes/left_finger_2.STL" />
      </geometry>
    </collision>
  </link>
  <joint
    name="left_finger_2_joint"
    type="revolute">
    <origin
      xyz="0.071343 0 0"
      rpy="-1.5708 0 0" />
    <parent
      link="left_finger_1" />
    <child
      link="left_finger_2" />
    <axis
      xyz="0 1 0" />
    <limit
      lower="-3.14"
      upper="3.14"
      effort="100.0"
      velocity="3.14" />
  </joint>
  <link
    name="right_finger_1">
    <inertial>
      <origin
        xyz="0.0362255356799372 7.19721504616189E-11 -4.18730362441444E-05"
        rpy="0 0 0" />
      <mass
        value="0.001" />
      <inertia
        ixx="6.64066668853769E-06"
        ixy="-5.31596785024297E-14"
        ixz="-1.58101059071538E-14"
        iyy="1.70445818730747E-05"
        iyz="1.13977089585789E-11"
        izz="1.11317984671144E-05" />
    </inertial>
    <visual>
      <origin
        xyz="0 0 0"
        rpy="0 0 0" />
      <geometry>
        <mesh
          filename="package://barista_robot/meshes/right_finger_1.STL" />
      </geometry>
      <material
        name="">
        <color
          rgba="1 0.501960784313725 0.501960784313725 1" />
      </material>
    </visual>
    <collision>
      <origin
        xyz="0 0 0"
        rpy="0 0 0" />
      <geometry>
        <mesh
          filename="package://barista_robot/meshes/right_finger_1.STL" />
      </geometry>
    </collision>
  </link>
  <joint
    name="right_finger_1_joint"
    type="revolute">
    <origin
      xyz="0.012988 0.061437 0"
      rpy="-3.1416 0 1.5708" />
    <parent
      link="gripper_base_link" />
    <child
      link="right_finger_1" />
    <axis
      xyz="0 0 1" />
    <limit
      lower="-3.14"
      upper="3.14"
      effort="100.0"
      velocity="3.14" />
  </joint>
  <link
    name="right_finger_2">
    <inertial>
      <origin
        xyz="0.0205613134938169 0.000122395880531645 -2.07395434159707E-10"
        rpy="0 0 0" />
      <mass
        value="0.001" />
      <inertia
        ixx="2.6334781516958E-07"
        ixy="1.21659199061431E-13"
        ixz="-2.86602558517981E-14"
        iyy="1.51982892750924E-06"
        iyz="1.85154993952589E-13"
        izz="1.68462676953666E-06" />
    </inertial>
    <visual>
      <origin
        xyz="0 0 0"
        rpy="0 0 0" />
      <geometry>
        <mesh
          filename="package://barista_robot/meshes/right_finger_2.STL" />
      </geometry>
      <material
        name="">
        <color
          rgba="1 0.501960784313725 0.501960784313725 1" />
      </material>
    </visual>
    <collision>
      <origin
        xyz="0 0 0"
        rpy="0 0 0" />
      <geometry>
        <mesh
          filename="package://barista_robot/meshes/right_finger_2.STL" />
      </geometry>
    </collision>
  </link>
  <joint
    name="right_finger_2_joint"
    type="revolute">
    <origin
      xyz="0.071343 0 0"
      rpy="-1.5708 0 0" />
    <parent
      link="right_finger_1" />
    <child
      link="right_finger_2" />
    <axis
      xyz="0 1 0" />
    <limit
      lower="-3.14"
      upper="3.14"
      effort="100.0"
      velocity="3.14" />
  </joint>
  <link
    name="camera_link">
    <inertial>
      <origin
        xyz="-2.54923859799305E-12 0.0074167211391849 -5.55111512312578E-17"
        rpy="0 0 0" />
      <mass
        value="0.001" />
      <inertia
        ixx="1.29743486402871E-07"
        ixy="3.74234603694889E-22"
        ixz="-6.94831714544543E-23"
        iyy="4.36359662905541E-07"
        iyz="-2.17496802313162E-22"
        izz="4.6673485435427E-07" />
    </inertial>
    <visual>
      <origin
        xyz="0 0 0"
        rpy="0 0 0" />
      <geometry>
        <mesh
          filename="package://barista_robot/meshes/camera_link.STL" />
      </geometry>
      <material
        name="">
        <color
          rgba="0.250980392156863 0.250980392156863 0.250980392156863 1" />
      </material>
    </visual>
    <collision>
      <origin
        xyz="0 0 0"
        rpy="0 0 0" />
      <geometry>
        <mesh
          filename="package://barista_robot/meshes/camera_link.STL" />
      </geometry>
    </collision>
  </link>
  <joint
    name="camera_joint_link"
    type="fixed">
    <origin
      xyz="0 0.0515 0.060233"
      rpy="0 -1.57 0" />
    <parent
      link="link_6" />
    <child
      link="camera_link" />
    <axis
      xyz="0 0 0" />
  </joint>

<!-- Add Gazebo plugin to camera_link -->
<gazebo reference="camera_link">
  <sensor type="camera" name="camera_sensor">
    <camera>
      <horizontal_fov>1.047</horizontal_fov> <!-- Field of view (in radians) -->
      <image>
        <width>640</width>
        <height>480</height>
        <format>R8G8B8</format> <!-- RGB8 format -->
      </image>
      <clip>
        <near>0.01</near>
        <far>100</far>
      </clip>
    </camera>
    <plugin name="camera_controller" filename="libgazebo_ros_camera.so">
      <ros>
        <namespace>/camera</namespace> <!-- Namespace for topics -->
        <argument>--ros-args</argument>
      </ros>
      <update_rate>30.0</update_rate>
      <image_topic_name>image_raw</image_topic_name>
      <camera_info_topic_name>camera_info</camera_info_topic_name>
    </plugin>
  </sensor>
</gazebo>


 <ros2_control name="GazeboSystem" type="system">
 <hardware>
     <plugin>gazebo_ros2_control/GazeboSystem</plugin>
 </hardware>


 # Position Controllers
  <joint name="left_finger_1_joint">
     <command_interface name="position">
         <param name="min">-6.28</param>
         <param name="max">6.28</param>
     </command_interface>
     <state_interface name="position"/>
     <state_interface name="velocity"/>
 </joint>

  <joint name="left_finger_2_joint">
     <command_interface name="position">
         <param name="min">-6.28</param>
         <param name="max">6.28</param>
     </command_interface>
     <state_interface name="position"/>
     <state_interface name="velocity"/>
 </joint>

   <joint name="right_finger_1_joint">
     <command_interface name="position">
         <param name="min">-6.28</param>
         <param name="max">6.28</param>
     </command_interface>
     <state_interface name="position"/>
     <state_interface name="velocity"/>
 </joint>

  <joint name="right_finger_2_joint">
     <command_interface name="position">
         <param name="min">-6.28</param>
         <param name="max">6.28</param>
     </command_interface>
     <state_interface name="position"/>
     <state_interface name="velocity"/>
 </joint>

 # Position Controllers

  <joint name="link_1_joint">
     <command_interface name="position">
         <param name="min">-6.28</param>
         <param name="max">6.28</param>
     </command_interface>
     <state_interface name="position"/>
     <state_interface name="velocity"/>
 </joint>

  <joint name="link_2_joint">
     <command_interface name="position">
         <param name="min">-6.28</param>
         <param name="max">6.28</param>
     </command_interface>
     <state_interface name="position"/>
     <state_interface name="velocity"/>
 </joint>

   <joint name="link_3_joint">
     <command_interface name="position">
         <param name="min">-6.28</param>
         <param name="max">6.28</param>
     </command_interface>
     <state_interface name="position"/>
     <state_interface name="velocity"/>
 </joint>

  <joint name="link_4_joint">
     <command_interface name="position">
         <param name="min">-6.28</param>
         <param name="max">6.28</param>
     </command_interface>
     <state_interface name="position"/>
     <state_interface name="velocity"/>
 </joint>

   <joint name="link_5_joint">
     <command_interface name="position">
         <param name="min">-6.28</param>
         <param name="max">6.28</param>
     </command_interface>
     <state_interface name="position"/>
     <state_interface name="velocity"/>
 </joint>

   <joint name="link_6_joint">
     <command_interface name="position">
         <param name="min">-6.28</param>
         <param name="max">6.28</param>
     </command_interface>
     <state_interface name="position"/>
     <state_interface name="velocity"/>
 </joint>
 
 

 # Effort Controllers
   <joint name="link_1_joint">
     <command_interface name="effort">
         <param name="min">0.0</param>
         <param name="max">100.0</param>
     </command_interface>
     <state_interface name="position"/>
     <state_interface name="velocity"/>
     <state_interface name="effort"/>
 </joint>

   <joint name="link_2_joint">
     <command_interface name="effort">
         <param name="min">0.0</param>
         <param name="max">100.0</param>
     </command_interface>
     <state_interface name="position"/>
     <state_interface name="velocity"/>
     <state_interface name="effort"/>
 </joint>

    <joint name="link_3_joint">
     <command_interface name="effort">
         <param name="min">0.0</param>
         <param name="max">100.0</param>
     </command_interface>
     <state_interface name="position"/>
     <state_interface name="velocity"/>
     <state_interface name="effort"/>
 </joint>

    <joint name="link_4_joint">
     <command_interface name="effort">
         <param name="min">0.0</param>
         <param name="max">100.0</param>
     </command_interface>
     <state_interface name="position"/>
     <state_interface name="velocity"/>
     <state_interface name="effort"/>
 </joint>

    <joint name="link_5_joint">
     <command_interface name="effort">
         <param name="min">0.0</param>
         <param name="max">100.0</param>
     </command_interface>
     <state_interface name="position"/>
     <state_interface name="velocity"/>
     <state_interface name="effort"/>
 </joint>

    <joint name="link_6_joint">
     <command_interface name="effort">
         <param name="min">0.0</param>
         <param name="max">100.0</param>
     </command_interface>
     <state_interface name="position"/>
     <state_interface name="velocity"/>
     <state_interface name="effort"/>
 </joint>

    <joint name="left_finger_1_joint">
     <command_interface name="effort">
         <param name="min">0.0</param>
         <param name="max">100.0</param>
     </command_interface>
     <state_interface name="position"/>
     <state_interface name="velocity"/>
     <state_interface name="effort"/>
 </joint>

     <joint name="left_finger_2_joint">
     <command_interface name="effort">
         <param name="min">0.0</param>
         <param name="max">100.0</param>
     </command_interface>
     <state_interface name="position"/>
     <state_interface name="velocity"/>
     <state_interface name="effort"/>
 </joint>

     <joint name="right_finger_1_joint">
     <command_interface name="effort">
         <param name="min">0.0</param>
         <param name="max">100.0</param>
     </command_interface>
     <state_interface name="position"/>
     <state_interface name="velocity"/>
     <state_interface name="effort"/>
 </joint>

     <joint name="right_finger_2_joint">
     <command_interface name="effort">
         <param name="min">0.0</param>
         <param name="max">100.0</param>
     </command_interface>
     <state_interface name="position"/>
     <state_interface name="velocity"/>
     <state_interface name="effort"/>
 </joint>

 </ros2_control>

  <gazebo>
      <plugin filename="libgazebo_ros2_control.so" name="gazebo_ros2_control">
          <parameters>$(find barista_robot)/config/control.yaml</parameters>
      </plugin>
  </gazebo>


  <gazebo reference="base_link">
    <xacro:grey_color />
  </gazebo>

  <gazebo reference="camera_link">
    <xacro:grey_color />
  </gazebo>

  <gazebo reference="robot_base">
    <xacro:red_color />
  </gazebo>

  <gazebo reference="link_1">
    <xacro:red_color />
  </gazebo>

  <gazebo reference="link_2">
    <xacro:red_color />
  </gazebo>
  
  <gazebo reference="link_3">
    <xacro:red_color />
  </gazebo>
  
  <gazebo reference="link_4">
    <xacro:red_color />
  </gazebo>

  <gazebo reference="link_5">
    <xacro:red_color />
  </gazebo>

  <gazebo reference="link_6">
    <xacro:red_color />
  </gazebo>

  <gazebo reference="gripper_base_link">
    <xacro:red_color />
  </gazebo>

  <gazebo reference="left_finger_1">
    <xacro:red_color />
  </gazebo>

  <gazebo reference="left_finger_2">
    <xacro:red_color />
  </gazebo>

  <gazebo reference="right_finger_1">
    <xacro:red_color />
  </gazebo>

  <gazebo reference="right_finger_2">
    <xacro:red_color />
  </gazebo>


</robot>